File: Subroutines/process_pdf/xrdmlread/GaMnAs_MAP.xrdml
<?xml version="1.0" encoding="UTF-8"?>
<xrdMeasurements xmlns="http://www.xrdml.com/XRDMeasurement/1.0" xmlns:xsi="http://www.w3.org/2001/XMLSchema-instance" xsi:schemaLocation="http://www.xrdml.com/XRDMeasurement/1.0 http://www.xrdml.com/XRDMeasurement/1.0/XRDMeasurement.xsd" status="Completed">
	<sample type="To be analyzed">
		<id>A012/2</id>
	</sample>
	<xrdMeasurement measurementType="Area measurement" status="Completed" measurementStepAxis="Omega">
		<comment>
			<entry>mapa pro 117</entry>
		</comment>
		<usedWavelength intended="K-Alpha 1">
			<kAlpha1 unit="Angstrom">1.5405980</kAlpha1>
			<kAlpha2 unit="Angstrom">1.5444260</kAlpha2>
			<kBeta unit="Angstrom">1.3922500</kBeta>
			<ratioKAlpha2KAlpha1>0.0000</ratioKAlpha2KAlpha1>
		</usedWavelength>
		<incidentBeamPath>
			<radius unit="mm">426.70</radius>
			<xRayTube id="1010048" name="PW3373/10 Cu LFF DK137621">
				<tension unit="kV">40</tension>
				<current unit="mA">35</current>
				<anodeMaterial>Cu</anodeMaterial>
				<focus type="Line">
					<length unit="mm">12.0</length>
					<width unit="mm">0.4</width>
					<takeOffAngle unit="deg">7.0</takeOffAngle>
				</focus>
			</xRayTube>
			<xRayMirror id="27010001" name="Inc. X-ray mirror Cu (MRD)" hybrid="false">
				<crystal type="Graded" shape="Parabolic">W/Si</crystal>
				<acceptanceAngle unit="deg">0.8</acceptanceAngle>
				<length unit="mm">60.0</length>
			</xRayMirror>
			<monochromator id="23010028" name="4xGe220 Asym. (mirror)" hybrid="false">
				<crystal type="Asymmetric" shape="Flat">Ge</crystal>
				<numberOfReflections>4</numberOfReflections>
				<hkl>
					<h>2</h>
					<k>2</k>
					<l>0</l>
				</hkl>
			</monochromator>
			<sollerSlit id="21010002" name="Soller 0.04 rad.">
				<opening unit="rad">0.0400</opening>
			</sollerSlit>
			<mask id="22040001" name="Crossed Slit Collimator (MRD)">
				<width unit="mm">4.00</width>
			</mask>
			<divergenceSlit id="22040001" name="Crossed Slit Collimator (MRD)" xsi:type="fixedDivergenceSlitType">
				<distanceToSample unit="mm">170.00</distanceToSample>
				<height unit="mm">1.00</height>
			</divergenceSlit>
		</incidentBeamPath>
		<sampleOffset>
			<position axis="2Theta" unit="deg">-0.0100</position>
			<position axis="Omega" unit="deg">0.0637</position>
			<position axis="Psi" unit="deg">0.80</position>
		</sampleOffset>
		<diffractedBeamPath>
			<radius unit="mm">320.00</radius>
			<monochromator id="23010018" name="Triple axis, 3-bounce" hybrid="false">
				<crystal type="Symmetric" shape="Flat">Ge</crystal>
				<numberOfReflections>3</numberOfReflections>
				<hkl>
					<h>2</h>
					<k>2</k>
					<l>0</l>
				</hkl>
			</monochromator>
			<detector id="7010011" name="PW3011/20 (Miniprop. large window)" xsi:type="pointDetectorType">
				<phd>
					<lowerLevel unit="%">35.0</lowerLevel>
					<upperLevel unit="%">80.0</upperLevel>
				</phd>
			</detector>
		</diffractedBeamPath>
		<measurementStepAxisCenter>
			<position axis="Omega" unit="deg">87.1811</position>
		</measurementStepAxisCenter>
		<scan appendNumber="0" mode="Continuous" scanAxis="Omega-2Theta" status="Completed">
			<header>
				<startTimeStamp>2004-12-16T22:23:34+01:00</startTimeStamp>
				<endTimeStamp>2004-12-16T22:27:36+01:00</endTimeStamp>
				<author>
					<name>MFF</name>
				</author>
				<source>
					<applicationSoftware version="2.0d">X'Pert Data Collector</applicationSoftware>
					<instrumentControlSoftware version="1.4 ">XPERT-PRO</instrumentControlSoftware>
					<instrumentID>0000000000005097</instrumentID>
				</source>
			</header>
			<scanAxisCenter>
				<position axis="2Theta" unit="deg">151.4814</position>
				<position axis="Omega" unit="deg">87.0811</position>
			</scanAxisCenter>
			<reflection>
				<material>GaAs [001]</material>
				<hkl>
					<h>1</h>
					<k>1</k>
					<l>7</l>
				</hkl>
				<unitCell>
					<alpha unit="deg">90.00000</alpha>
					<beta unit="deg">90.00000</beta>
					<gamma unit="deg">90.00000</gamma>
					<a unit="Angstrom">5.65368</a>
					<b unit="Angstrom">5.65368</b>
					<c unit="Angstrom">5.65368</c>
				</unitCell>
			</reflection>
			<dataPoints>
				<positions axis="2Theta" unit="deg">
					<startPosition>149.1014</startPosition>
					<endPosition>153.8614</endPosition>
				</positions>
				<positions axis="Omega" unit="deg">
					<startPosition>85.8911</startPosition>
					<endPosition>88.2711</endPosition>
				</positions>
				<positions axis="Phi" unit="deg">
					<commonPosition>180.00</commonPosition>
				</positions>
				<positions axis="Psi" unit="deg">
					<commonPosition>1.45</commonPosition>
				</positions>
				<positions axis="X" unit="mm">
					<commonPosition>3.00</commonPosition>
				</positions>
				<positions axis="Y" unit="mm">
					<commonPosition>23.50</commonPosition>
				</positions>
				<positions axis="Z" unit="mm">
					<commonPosition>8.073</commonPosition>
				</positions>
				<commonCountingTime unit="seconds">1.00</commonCountingTime>
				<intensities unit="counts">0 0 1 1 1 0 0 0 0 0 0 0 2 0 0 0 0 1 0 0 0 0 0 0 0 0 0 0 0 0 0 2 0 0 1 0 0 0 0 2 0 0 0 0 1 1 0 0 0 0 1 0 1 1 0 1 1 1 0 0 0 1 0 0 0 0 0 0 0 1 0 0 0 0 1 0 0 0 1 0 0 0 1 0 0 0 0 1 0 1 0 0 0 0 1 0 0 1 1 0 1 0 0 1 0 0 2 1 1 1 0 0 0 1 0 2 0 0 0 0 0 0 0 0 1 0 1 2 0 1 1 0 1 0 0 0 2 0 2 0 0 2 2 0 1 0 0 1 1 1 0 2 0 0 1 1 2 1 0 1 1 1 0 0 2 0 1 1 1 0 1 0 1 0 0 1 2 1 1 3 0 2 0 2 2 3 1 2 0 3 2 1 0 3 1 1 2 2 3 3 3 2 3 0 5 2 1 3 1 1 4 2 2 2 6 1 3 2 5 1 5 2 1 1 0 2 1 2 3 5 3 1 3 0 0 6 0 0 0</intensities>
			</dataPoints>
		</scan>
		<scan appendNumber="0" mode="Continuous" scanAxis="Omega-2Theta" status="Completed">
			<header>
				<startTimeStamp>2004-12-16T22:27:49+01:00</startTimeStamp>
				<endTimeStamp>2004-12-16T22:31:52+01:00</endTimeStamp>
				<author>
					<name>MFF</name>
				</author>
				<source>
					<applicationSoftware version="2.0d">X'Pert Data Collector</applicationSoftware>
					<instrumentControlSoftware version="1.4 ">XPERT-PRO</instrumentControlSoftware>
					<instrumentID>0000000000005097</instrumentID>
				</source>
			</header>
			<scanAxisCenter>
				<position axis="2Theta" unit="deg">151.4814</position>
				<position axis="Omega" unit="deg">87.0821</position>
			</scanAxisCenter>
			<reflection>
				<material>GaAs [001]</material>
				<hkl>
					<h>1</h>
					<k>1</k>
					<l>7</l>
				</hkl>
				<unitCell>
					<alpha unit="deg">90.00000</alpha>
					<beta unit="deg">90.00000</beta>
					<gamma unit="deg">90.00000</gamma>
					<a unit="Angstrom">5.65368</a>
					<b unit="Angstrom">5.65368</b>
					<c unit="Angstrom">5.65368</c>
				</unitCell>
			</reflection>
			<dataPoints>
				<positions axis="2Theta" unit="deg">
					<startPosition>149.1014</startPosition>
					<endPosition>153.8614</endPosition>
				</positions>
				<positions axis="Omega" unit="deg">
					<startPosition>85.8921</startPosition>
					<endPosition>88.2721</endPosition>
				</positions>
				<positions axis="Phi" unit="deg">
					<commonPosition>180.00</commonPosition>
				</positions>
				<positions axis="Psi" unit="deg">
					<commonPosition>1.45</commonPosition>
				</positions>
				<positions axis="X" unit="mm">
					<commonPosition>3.00</commonPosition>
				</positions>
				<positions axis="Y" unit="mm">
					<commonPosition>23.50</commonPosition>
				</positions>
				<positions axis="Z" unit="mm">
					<commonPosition>8.073</commonPosition>
				</positions>
				<commonCountingTime unit="seconds">1.00</commonCountingTime>
				<intensities unit="counts">0 0 0 0 0 0 0 0 0 0 0 0 0 0 1 3 0 1 0 1 0 1 0 0 0 0 0 0 0 0 0 0 2 0 0 0 0 0 0 0 0 0 1 0 1 1 0 0 0 1 0 1 0 0 0 1 0 0 0 0 0 0 1 1 0 0 0 0 0 0 0 0 1 0 0 0 2 0 1 0 1 0 0 0 0 0 0 2 0 0 0 1 1 1 0 1 0 1 2 1 0 0 1 0 0 0 0 0 0 0 0 0 0 1 0 0 0 0 1 0 1 1 1 0 0 2 0 0 0 0 0 0 0 1 0 1 2 0 1 0 0 0 1 0 0 1 0 1 2 1 0 1 0 0 1 2 3 0 1 0 1 1 2 2 0 0 1 0 1 1 0 1 0 0 1 0 1 1 2 0 4 1 0 2 2 2 2 6 0 1 2 0 2 0 2 2 2 2 0 3 2 0 1 1 2 0 0 1 4 2 0 3 3 0 2 2 2 0 3 1 4 2 2 1 4 2 4 1 1 2 0 1 4 0 1 5 1 1 4</intensities>
			</dataPoints>
		</scan>
		<scan appendNumber="0" mode="Continuous" scanAxis="Omega-2Theta" status="Completed">
			<header>
				<startTimeStamp>2004-12-16T22:32:08+01:00</startTimeStamp>
				<endTimeStamp>2004-12-16T22:36:10+01:00</endTimeStamp>
				<author>
					<name>MFF</name>
				</author>
				<source>
					<applicationSoftware version="2.0d">X'Pert Data Collector</applicationSoftware>
					<instrumentControlSoftware version="1.4 ">XPERT-PRO</instrumentControlSoftware>
					<instrumentID>0000000000005097</instrumentID>
				</source>
			</header>
			<scanAxisCenter>
				<position axis="2Theta" unit="deg">151.4814</position>
				<position axis="Omega" unit="deg">87.0831</position>
			</scanAxisCenter>
			<reflection>
				<material>GaAs [001]</material>
				<hkl>
					<h>1</h>
					<k>1</k>
					<l>7</l>
				</hkl>
				<unitCell>
					<alpha unit="deg">90.00000</alpha>
					<beta unit="deg">90.00000</beta>
					<gamma unit="deg">90.00000</gamma>
					<a unit="Angstrom">5.65368</a>
					<b unit="Angstrom">5.65368</b>
					<c unit="Angstrom">5.65368</c>
				</unitCell>
			</reflection>
			<dataPoints>
				<positions axis="2Theta" unit="deg">
					<startPosition>149.1014</startPosition>
					<endPosition>153.8614</endPosition>
				</positions>
				<positions axis="Omega" unit="deg">
					<startPosition>85.8931</startPosition>
					<endPosition>88.2731</endPosition>
				</positions>
				<positions axis="Phi" unit="deg">
					<commonPosition>180.00</commonPosition>
				</positions>
				<positions axis="Psi" unit="deg">
					<commonPosition>1.45</commonPosition>
				</positions>
				<positions axis="X" unit="mm">
					<commonPosition>3.00</commonPosition>
				</positions>
				<positions axis="Y" unit="mm">
					<commonPosition>23.50</commonPosition>
				</positions>
				<positions axis="Z" unit="mm">
					<commonPosition>8.073</commonPosition>
				</positions>
				<commonCountingTime unit="seconds">1.00</commonCountingTime>
				<intensities unit="counts">0 0 0 1 0 0 0 1 1 0 0 0 1 0 0 2 0 0 0 0 0 0 0 0 0 0 0 0 0 0 0 1 0 0 0 0 1 0 0 0 0 0 0 0 2 0 0 0 0 0 0 0 1 0 0 0 0 1 0 1 0 1 0 1 0 0 1 0 0 0 0 1 0 0 0 1 1 1 0 2 1 1 3 1 1 0 0 1 0 0 0 0 1 3 0 0 0 1 0 0 0 0 0 0 2 0 1 1 0 0 2 0 0 2 0 1 0 2 0 1 1 0 0 2 0 0 0 0 1 0 0 1 1 0 1 1 1 1 0 0 0 0 0 0 0 0 1 0 0 1 0 0 0 0 0 3 0 1 0 0 0 2 1 0 0 1 0 2 3 0 0 1 1 1 1 4 0 2 1 1 1 1 1 2 1 1 1 1 0 1 0 0 5 2 3 2 1 2 5 0 2 2 1 7 2 2 2 1 1 2 2 0 0 0 3 3 5 4 1 1 3 3 3 3 3 1 4 3 0 3 3 3 1 1 1 3 2 1 1</intensities>
			</dataPoints>
		</scan>
		<scan appendNumber="0" mode="Continuous" scanAxis="Omega-2Theta" status="Completed">
			<header>
				<startTimeStamp>2004-12-16T22:36:24+01:00</startTimeStamp>
				<endTimeStamp>2004-12-16T22:40:26+01:00</endTimeStamp>
				<author>
					<name>MFF</name>
				</author>
				<source>
					<applicationSoftware version="2.0d">X'Pert Data Collector</applicationSoftware>
					<instrumentControlSoftware version="1.4 ">XPERT-PRO</instrumentControlSoftware>
					<instrumentID>0000000000005097</instrumentID>
				</source>
			</header>
			<scanAxisCenter>
				<position axis="2Theta" unit="deg">151.4814</position>
				<position axis="Omega" unit="deg">87.0841</position>
			</scanAxisCenter>
			<reflection>
				<material>GaAs [001]</material>
				<hkl>
					<h>1</h>
					<k>1</k>
					<l>7</l>
				</hkl>
				<unitCell>
					<alpha unit="deg">90.00000</alpha>
					<beta unit="deg">90.00000</beta>
					<gamma unit="deg">90.00000</gamma>
					<a unit="Angstrom">5.65368</a>
					<b unit="Angstrom">5.65368</b>
					<c unit="Angstrom">5.65368</c>
				</unitCell>
			</reflection>
			<dataPoints>
				<positions axis="2Theta" unit="deg">
					<startPosition>149.1014</startPosition>
					<endPosition>153.8614</endPosition>
				</positions>
				<positions axis="Omega" unit="deg">
					<startPosition>85.8941</startPosition>
					<endPosition>88.2741</endPosition>
				</positions>
				<positions axis="Phi" unit="deg">
					<commonPosition>180.00</commonPosition>
				</positions>
				<positions axis="Psi" unit="deg">
					<commonPosition>1.45</commonPosition>
				</positions>
				<positions axis="X" unit="mm">
					<commonPosition>3.00</commonPosition>
				</positions>
				<positions axis="Y" unit="mm">
					<commonPosition>23.50</commonPosition>
				</positions>
				<positions axis="Z" unit="mm">
					<commonPosition>8.073</commonPosition>
				</positions>
				<commonCountingTime unit="seconds">1.00</commonCountingTime>
				<intensities unit="counts">0 0 0 1 0 0 0 0 1 0 0 0 0 0 0 0 0 0 0 1 0 0 0 0 0 0 0 0 1 0 0 0 0 1 0 0 0 0 1 0 0 0 0 0 1 0 0 0 0 1 1 0 0 0 0 1 0 0 0 0 0 0 0 2 0 0 0 1 0 0 0 0 0 1 0 1 0 0 0 1 0 0 1 0 0 1 0 0 3 0 0 0 0 0 0 0 1 0 0 0 1 0 1 0 0 0 0 0 0 0 1 1 0 1 0 2 0 0 1 0 1 1 2 3 1 1 2 2 1 1 1 1 0 0 1 0 1 0 0 0 0 1 0 0 1 0 1 2 1 1 0 3 0 2 0 1 0 0 2 3 2 0 2 1 0 0 1 0 0 0 2 3 1 2 0 1 0 1 1 2 1 1 1 1 0 5 1 0 1 0 1 2 0 4 1 2 2 2 1 1 2 4 4 2 4 3 3 2 0 4 6 2 2 6 4 3 1 1 2 2 5 1 2 1 3 2 2 1 2 1 1 4 1 3 1 1 0 1 3</intensities>
			</dataPoints>
		</scan>
		<scan appendNumber="0" mode="Continuous" scanAxis="Omega-2Theta" status="Completed">
			<header>
				<startTimeStamp>2004-12-16T22:40:37+01:00</startTimeStamp>
				<endTimeStamp>2004-12-16T22:44:39+01:00</endTimeStamp>
				<author>
					<name>MFF</name>
				</author>
				<source>
					<applicationSoftware version="2.0d">X'Pert Data Collector</applicationSoftware>
					<instrumentControlSoftware version="1.4 ">XPERT-PRO</instrumentControlSoftware>
					<instrumentID>0000000000005097</instrumentID>
				</source>
			</header>
			<scanAxisCenter>
				<position axis="2Theta" unit="deg">151.4814</position>
				<position axis="Omega" unit="deg">87.0851</position>
			</scanAxisCenter>
			<reflection>
				<material>GaAs [001]</material>
				<hkl>
					<h>1</h>
					<k>1</k>
					<l>7</l>
				</hkl>
				<unitCell>
					<alpha unit="deg">90.00000</alpha>
					<beta unit="deg">90.00000</beta>
					<gamma unit="deg">90.00000</gamma>
					<a unit="Angstrom">5.65368</a>
					<b unit="Angstrom">5.65368</b>
					<c unit="Angstrom">5.65368</c>
				</unitCell>
			</reflection>
			<dataPoints>
				<positions axis="2Theta" unit="deg">
					<startPosition>149.1014</startPosition>
					<endPosition>153.8614</endPosition>
				</positions>
				<positions axis="Omega" unit="deg">
					<startPosition>85.8951</startPosition>
					<endPosition>88.2751</endPosition>
				</positions>
				<positions axis="Phi" unit="deg">
					<commonPosition>180.00</commonPosition>
				</positions>
				<positions axis="Psi" unit="deg">
					<commonPosition>1.45</commonPosition>
				</positions>
				<positions axis="X" unit="mm">
					<commonPosition>3.00</commonPosition>
				</positions>
				<positions axis="Y" unit="mm">
					<commonPosition>23.50</commonPosition>
				</positions>
				<positions axis="Z" unit="mm">
					<commonPosition>8.073</commonPosition>
				</positions>
				<commonCountingTime unit="seconds">1.00</commonCountingTime>
				<intensities unit="counts">0 0 0 0 0 0 0 0 0 1 1 0 0 0 0 2 0 0 0 1 0 0 0 1 0 1 0 0 0 1 0 0 0 0 0 0 0 0 0 0 1 0 0 0 1 1 0 0 0 2 0 1 0 0 1 0 0 0 1 1 0 0 1 0 0 0 0 1 0 1 0 0 0 0 1 0 0 0 1 0 0 0 1 0 1 0 0 0 0 0 0 0 0 0 1 1 0 2 0 1 0 0 1 1 0 0 0 1 1 1 0 3 0 0 0 0 1 1 0 0 0 1 0 0 1 0 1 0 0 0 1 1 2 1 0 1 0 0 1 0 0 0 0 0 1 0 0 0 0 0 0 0 0 1 1 0 2 0 0 1 2 0 0 0 2 0 2 2 0 1 3 0 1 2 1 2 0 0 0 2 1 1 3 3 1 0 2 1 0 2 1 0 2 3 3 2 1 2 3 2 2 1 1 3 0 3 7 1 1 1 1 3 3 4 7 2 1 2 2 2 1 5 6 1 3 4 2 3 2 2 3 0 1 1 2 1 2 0 3</intensities>
			</dataPoints>
		</scan>
		<scan appendNumber="0" mode="Continuous" scanAxis="Omega-2Theta" status="Completed">
			<header>
				<startTimeStamp>2004-12-16T22:44:50+01:00</startTimeStamp>
				<endTimeStamp>2004-12-16T22:48:52+01:00</endTimeStamp>
				<author>
					<name>MFF</name>
				</author>
				<source>
					<applicationSoftware version="2.0d">X'Pert Data Collector</applicationSoftware>
					<instrumentControlSoftware version="1.4 ">XPERT-PRO</instrumentControlSoftware>
					<instrumentID>0000000000005097</instrumentID>
				</source>
			</header>
			<scanAxisCenter>
				<position axis="2Theta" unit="deg">151.4814</position>
				<position axis="Omega" unit="deg">87.0861</position>
			</scanAxisCenter>
			<reflection>
				<material>GaAs [001]</material>
				<hkl>
					<h>1</h>
					<k>1</k>
					<l>7</l>
				</hkl>
				<unitCell>
					<alpha unit="deg">90.00000</alpha>
					<beta unit="deg">90.00000</beta>
					<gamma unit="deg">90.00000</gamma>
					<a unit="Angstrom">5.65368</a>
					<b unit="Angstrom">5.65368</b>
					<c unit="Angstrom">5.65368</c>
				</unitCell>
			</reflection>
			<dataPoints>
				<positions axis="2Theta" unit="deg">
					<startPosition>149.1014</startPosition>
					<endPosition>153.8614</endPosition>
				</positions>
				<positions axis="Omega" unit="deg">
					<startPosition>85.8961</startPosition>
					<endPosition>88.2761</endPosition>
				</positions>
				<positions axis="Phi" unit="deg">
					<commonPosition>180.00</commonPosition>
				</positions>
				<positions axis="Psi" unit="deg">
					<commonPosition>1.45</commonPosition>
				</positions>
				<positions axis="X" unit="mm">
					<commonPosition>3.00</commonPosition>
				</positions>
				<positions axis="Y" unit="mm">
					<commonPosition>23.50</commonPosition>
				</positions>
				<positions axis="Z" unit="mm">
					<commonPosition>8.073</commonPosition>
				</positions>
				<commonCountingTime unit="seconds">1.00</commonCountingTime>
				<intensities unit="counts">0 1 0 0 0 0 0 0 0 0 0 0 0 0 0 0 0 0 0 1 0 0 0 0 0 1 0 1 0 0 0 0 2 0 0 1 1 0 0 0 0 1 0 0 0 1 0 0 0 0 0 0 0 0 0 0 0 0 0 0 0 0 0 0 0 0 0 1 1 0 0 0 0 0 0 0 0 0 0 0 0 1 0 0 2 0 0 0 0 0 0 0 0 0 0 1 0 0 0 0 0 1 2 0 0 0 1 2 0 0 0 0 0 0 0 1 0 0 0 0 0 0 0 0 0 1 0 0 1 0 0 0 0 0 1 1 0 1 1 1 0 0 2 1 0 0 0 1 0 1 1 0 0 1 0 0 4 0 0 1 2 1 1 1 0 1 0 0 1 3 1 0 2 1 1 1 0 0 2 1 0 1 1 0 3 1 3 1 3 1 2 1 1 3 2 2 3 5 3 1 4 2 3 2 1 2 3 4 1 0 3 1 1 0 4 1 3 1 4 2 2 1 4 3 1 2 1 1 3 1 2 5 0 1 2 1 0 1 1</intensities>
			</dataPoints>
		</scan>
		<scan appendNumber="0" mode="Continuous" scanAxis="Omega-2Theta" status="Completed">
			<header>
				<startTimeStamp>2004-12-16T22:49:07+01:00</startTimeStamp>
				<endTimeStamp>2004-12-16T22:53:08+01:00</endTimeStamp>
				<author>
					<name>MFF</name>
				</author>
				<source>
					<applicationSoftware version="2.0d">X'Pert Data Collector</applicationSoftware>
					<instrumentControlSoftware version="1.4 ">XPERT-PRO</instrumentControlSoftware>
					<instrumentID>0000000000005097</instrumentID>
				</source>
			</header>
			<scanAxisCenter>
				<position axis="2Theta" unit="deg">151.4814</position>
				<position axis="Omega" unit="deg">87.0871</position>
			</scanAxisCenter>
			<reflection>
				<material>GaAs [001]</material>
				<hkl>
					<h>1</h>
					<k>1</k>
					<l>7</l>
				</hkl>
				<unitCell>
					<alpha unit="deg">90.00000</alpha>
					<beta unit="deg">90.00000</beta>
					<gamma unit="deg">90.00000</gamma>
					<a unit="Angstrom">5.65368</a>
					<b unit="Angstrom">5.65368</b>
					<c unit="Angstrom">5.65368</c>
				</unitCell>
			</reflection>
			<dataPoints>
				<positions axis="2Theta" unit="deg">
					<startPosition>149.1014</startPosition>
					<endPosition>153.8614</endPosition>
				</positions>
				<positions axis="Omega" unit="deg">
					<startPosition>85.8971</startPosition>
					<endPosition>88.2771</endPosition>
				</positions>
				<positions axis="Phi" unit="deg">
					<commonPosition>180.00</commonPosition>
				</positions>
				<positions axis="Psi" unit="deg">
					<commonPosition>1.45</commonPosition>
				</positions>
				<positions axis="X" unit="mm">
					<commonPosition>3.00</commonPosition>
				</positions>
				<positions axis="Y" unit="mm">
					<commonPosition>23.50</commonPosition>
				</positions>
				<positions axis="Z" unit="mm">
					<commonPosition>8.073</commonPosition>
				</positions>
				<commonCountingTime unit="seconds">1.00</commonCountingTime>
				<intensities unit="counts">0 0 0 0 0 0 0 0 0 1 0 0 0 1 0 0 0 0 0 0 0 0 1 0 0 0 0 0 1 0 1 1 0 0 0 0 0 0 0 0 1 0 1 1 1 0 1 0 0 1 0 1 0 0 0 1 0 0 1 0 2 0 0 0 1 0 0 0 0 1 1 0 0 0 1 1 0 0 0 1 0 1 0 0 0 1 0 0 1 1 2 0 0 0 1 0 1 0 0 0 0 2 0 0 0 0 0 0 0 0 0 0 0 3 0 1 1 1 1 0 0 0 0 1 1 1 0 0 2 2 0 0 0 0 0 0 1 2 1 0 1 0 1 0 1 1 2 1 0 1 0 1 1 0 0 1 1 1 0 1 1 1 1 1 2 1 0 0 1 0 2 0 0 1 2 1 1 1 2 1 0 2 0 2 1 0 1 0 1 2 2 2 0 3 4 5 2 1 0 4 1 2 1 4 1 4 2 3 3 2 2 4 4 0 2 1 3 4 1 0 2 5 5 5 1 4 2 0 3 3 3 3 1 3 6 0 1 1 0</intensities>
			</dataPoints>
		</scan>
		<scan appendNumber="0" mode="Continuous" scanAxis="Omega-2Theta" status="Completed">
			<header>
				<startTimeStamp>2004-12-16T22:53:21+01:00</startTimeStamp>
				<endTimeStamp>2004-12-16T22:57:23+01:00</endTimeStamp>
				<author>
					<name>MFF</name>
				</author>
				<source>
					<applicationSoftware version="2.0d">X'Pert Data Collector</applicationSoftware>
					<instrumentControlSoftware version="1.4 ">XPERT-PRO</instrumentControlSoftware>
					<instrumentID>0000000000005097</instrumentID>
				</source>
			</header>
			<scanAxisCenter>
				<position axis="2Theta" unit="deg">151.4814</position>
				<position axis="Omega" unit="deg">87.0881</position>
			</scanAxisCenter>
			<reflection>
				<material>GaAs [001]</material>
				<hkl>
					<h>1</h>
					<k>1</k>
					<l>7</l>
				</hkl>
				<unitCell>
					<alpha unit="deg">90.00000</alpha>
					<beta unit="deg">90.00000</beta>
					<gamma unit="deg">90.00000</gamma>
					<a unit="Angstrom">5.65368</a>
					<b unit="Angstrom">5.65368</b>
					<c unit="Angstrom">5.65368</c>
				</unitCell>
			</reflection>
			<dataPoints>
				<positions axis="2Theta" unit="deg">
					<startPosition>149.1014</startPosition>
					<endPosition>153.8614</endPosition>
				</positions>
				<positions axis="Omega" unit="deg">
					<startPosition>85.8981</startPosition>
					<endPosition>88.2781</endPosition>
				</positions>
				<positions axis="Phi" unit="deg">
					<commonPosition>180.00</commonPosition>
				</positions>
				<positions axis="Psi" unit="deg">
					<commonPosition>1.45</commonPosition>
				</positions>
				<positions axis="X" unit="mm">
					<commonPosition>3.00</commonPosition>
				</positions>
				<positions axis="Y" unit="mm">
					<commonPosition>23.50</commonPosition>
				</positions>
				<positions axis="Z" unit="mm">
					<commonPosition>8.073</commonPosition>
				</positions>
				<commonCountingTime unit="seconds">1.00</commonCountingTime>
				<intensities unit="counts">0 0 0 0 1 0 0 0 0 1 0 0 0 1 0 0 0 0 1 0 0 0 0 0 0 0 0 0 1 0 0 0 0 0 0 1 0 1 0 0 0 0 0 0 0 0 0 1 0 0 0 0 0 0 0 0 0 0 1 0 0 0 0 0 0 0 0 1 1 0 0 1 0 0 0 0 0 0 0 0 0 0 0 0 0 0 0 0 1 0 0 0 0 0 1 0 0 0 1 1 0 2 1 0 2 1 0 0 3 0 0 1 0 0 0 0 2 0 0 0 0 1 0 0 2 0 0 0 1 0 0 0 0 0 0 2 0 0 0 0 1 0 1 2 1 0 1 0 0 0 2 0 0 2 1 1 0 0 1 0 0 0 1 1 1 1 2 1 1 1 0 2 3 0 0 1 0 3 0 1 0 2 1 1 0 0 2 1 2 2 0 1 1 2 2 2 4 0 2 1 2 4 3 2 5 3 3 2 4 6 4 1 3 3 1 1 2 2 0 4 5 3 4 4 2 2 2 3 2 1 1 2 1 5 2 1 0 0 2</intensities>
			</dataPoints>
		</scan>
		<scan appendNumber="0" mode="Continuous" scanAxis="Omega-2Theta" status="Completed">
			<header>
				<startTimeStamp>2004-12-16T22:57:33+01:00</startTimeStamp>
				<endTimeStamp>2004-12-16T23:01:35+01:00</endTimeStamp>
				<author>
					<name>MFF</name>
				</author>
				<source>
					<applicationSoftware version="2.0d">X'Pert Data Collector</applicationSoftware>
					<instrumentControlSoftware version="1.4 ">XPERT-PRO</instrumentControlSoftware>
					<instrumentID>0000000000005097</instrumentID>
				</source>
			</header>
			<scanAxisCenter>
				<position axis="2Theta" unit="deg">151.4814</position>
				<position axis="Omega" unit="deg">87.0891</position>
			</scanAxisCenter>
			<reflection>
				<material>GaAs [001]</material>
				<hkl>
					<h>1</h>
					<k>1</k>
					<l>7</l>
				</hkl>
				<unitCell>
					<alpha unit="deg">90.00000</alpha>
					<beta unit="deg">90.00000</beta>
					<gamma unit="deg">90.00000</gamma>
					<a unit="Angstrom">5.65368</a>
					<b unit="Angstrom">5.65368</b>
					<c unit="Angstrom">5.65368</c>
				</unitCell>
			</reflection>
			<dataPoints>
				<positions axis="2Theta" unit="deg">
					<startPosition>149.1014</startPosition>
					<endPosition>153.8614</endPosition>
				</positions>
				<positions axis="Omega" unit="deg">
					<startPosition>85.8991</startPosition>
					<endPosition>88.2791</endPosition>
				</positions>
				<positions axis="Phi" unit="deg">
					<commonPosition>180.00</commonPosition>
				</positions>
				<positions axis="Psi" unit="deg">
					<commonPosition>1.45</commonPosition>
				</positions>
				<positions axis="X" unit="mm">
					<commonPosition>3.00</commonPosition>
				</positions>
				<positions axis="Y" unit="mm">
					<commonPosition>23.50</commonPosition>
				</positions>
				<positions axis="Z" unit="mm">
					<commonPosition>8.073</commonPosition>
				</positions>
				<commonCountingTime unit="seconds">1.00</commonCountingTime>
				<intensities unit="counts">1 0 0 0 0 0 0 0 1 0 0 0 0 0 0 0 0 1 0 0 0 1 0 0 0 0 2 1 0 1 0 0 0 0 0 0 0 0 0 2 0 0 0 0 2 0 0 0 0 0 1 0 0 0 0 1 1 1 0 0 1 0 0 0 0 0 0 1 0 0 0 0 0 0 0 0 1 0 0 0 1 1 0 0 1 0 0 0 0 0 2 0 0 0 2 0 0 0 1 0 0 0 1 0 0 1 0 2 0 1 0 0 0 0 2 1 0 0 1 0 1 0 1 2 2 1 0 0 1 1 0 1 0 0 0 0 0 2 2 1 0 0 1 0 0 0 0 1 2 1 1 2 1 2 1 0 1 0 0 1 0 0 0 1 1 1 0 0 0 0 0 3 2 0 0 0 1 3 3 1 1 0 1 1 1 2 1 1 1 1 1 1 0 4 2 0 2 2 3 4 3 2 5 5 3 5 2 3 3 5 3 4 4 1 3 6 6 2 1 6 3 3 4 2 3 4 1 0 2 1 2 3 1 6 0 3 4 2 0</intensities>
			</dataPoints>
		</scan>
		<scan appendNumber="0" mode="Continuous" scanAxis="Omega-2Theta" status="Completed">
			<header>
				<startTimeStamp>2004-12-16T23:01:49+01:00</startTimeStamp>
				<endTimeStamp>2004-12-16T23:05:50+01:00</endTimeStamp>
				<author>
					<name>MFF</name>
				</author>
				<source>
					<applicationSoftware version="2.0d">X'Pert Data Collector</applicationSoftware>
					<instrumentControlSoftware version="1.4 ">XPERT-PRO</instrumentControlSoftware>
					<instrumentID>0000000000005097</instrumentID>
				</source>
			</header>
			<scanAxisCenter>
				<position axis="2Theta" unit="deg">151.4814</position>
				<position axis="Omega" unit="deg">87.0901</position>
			</scanAxisCenter>
			<reflection>
				<material>GaAs [001]</material>
				<hkl>
					<h>1</h>
					<k>1</k>
					<l>7</l>
				</hkl>
				<unitCell>
					<alpha unit="deg">90.00000</alpha>
					<beta unit="deg">90.00000</beta>
					<gamma unit="deg">90.00000</gamma>
					<a unit="Angstrom">5.65368</a>
					<b unit="Angstrom">5.65368</b>
					<c unit="Angstrom">5.65368</c>
				</unitCell>
			</reflection>
			<dataPoints>
				<positions axis="2Theta" unit="deg">
					<startPosition>149.1014</startPosition>
					<endPosition>153.8614</endPosition>
				</positions>
				<positions axis="Omega" unit="deg">
					<startPosition>85.9001</startPosition>
					<endPosition>88.2801</endPosition>
				</positions>
				<positions axis="Phi" unit="deg">
					<commonPosition>180.00</commonPosition>
				</positions>
				<positions axis="Psi" unit="deg">
					<commonPosition>1.45</commonPosition>
				</positions>
				<positions axis="X" unit="mm">
					<commonPosition>3.00</commonPosition>
				</positions>
				<positions axis="Y" unit="mm">
					<commonPosition>23.50</commonPosition>
				</positions>
				<positions axis="Z" unit="mm">
					<commonPosition>8.073</commonPosition>
				</positions>
				<commonCountingTime unit="seconds">1.00</commonCountingTime>
				<intensities unit="counts">0 0 1 1 0 0 0 0 1 0 0 0 0 0 0 1 1 0 0 0 1 1 0 1 1 0 0 0 0 0 0 0 2 0 0 0 0 1 0 0 0 0 0 0 0 0 0 1 1 0 0 1 0 1 0 1 1 1 0 0 0 2 0 1 0 1 0 3 0 0 1 0 0 0 2 0 0 0 0 2 0 0 0 0 0 0 0 0 0 0 0 0 0 0 0 0 0 0 1 0 0 1 0 0 0 0 2 0 0 1 0 0 0 0 0 0 0 1 1 1 0 4 2 0 1 1 1 0 0 0 1 0 1 1 0 0 0 1 0 0 0 1 0 2 0 0 2 0 1 3 3 0 2 1 0 1 1 1 0 1 0 1 1 2 0 1 1 2 0 0 1 2 2 1 1 2 1 2 3 2 0 2 2 3 3 0 3 2 1 0 2 0 0 1 0 3 2 1 6 1 1 1 2 3 3 3 3 4 2 5 2 1 0 3 2 6 3 3 0 2 4 1 6 3 4 3 3 2 6 1 2 3 1 3 5 1 0 0 2</intensities>
			</dataPoints>
		</scan>
		<scan appendNumber="0" mode="Continuous" scanAxis="Omega-2Theta" status="Completed">
			<header>
				<startTimeStamp>2004-12-16T23:06:02+01:00</startTimeStamp>
				<endTimeStamp>2004-12-16T23:10:04+01:00</endTimeStamp>
				<author>
					<name>MFF</name>
				</author>
				<source>
					<applicationSoftware version="2.0d">X'Pert Data Collector</applicationSoftware>
					<instrumentControlSoftware version="1.4 ">XPERT-PRO</instrumentControlSoftware>
					<instrumentID>0000000000005097</instrumentID>
				</source>
			</header>
			<scanAxisCenter>
				<position axis="2Theta" unit="deg">151.4814</position>
				<position axis="Omega" unit="deg">87.0911</position>
			</scanAxisCenter>
			<reflection>
				<material>GaAs [001]</material>
				<hkl>
					<h>1</h>
					<k>1</k>
					<l>7</l>
				</hkl>
				<unitCell>
					<alpha unit="deg">90.00000</alpha>
					<beta unit="deg">90.00000</beta>
					<gamma unit="deg">90.00000</gamma>
					<a unit="Angstrom">5.65368</a>
					<b unit="Angstrom">5.65368</b>
					<c unit="Angstrom">5.65368</c>
				</unitCell>
			</reflection>
			<dataPoints>
				<positions axis="2Theta" unit="deg">
					<startPosition>149.1014</startPosition>
					<endPosition>153.8614</endPosition>
				</positions>
				<positions axis="Omega" unit="deg">
					<startPosition>85.9011</startPosition>
					<endPosition>88.2811</endPosition>
				</positions>
				<positions axis="Phi" unit="deg">
					<commonPosition>180.00</commonPosition>
				</positions>
				<positions axis="Psi" unit="deg">
					<commonPosition>1.45</commonPosition>
				</positions>
				<positions axis="X" unit="mm">
					<commonPosition>3.00</commonPosition>
				</positions>
				<positions axis="Y" unit="mm">
					<commonPosition>23.50</commonPosition>
				</positions>
				<positions axis="Z" unit="mm">
					<commonPosition>8.073</commonPosition>
				</positions>
				<commonCountingTime unit="seconds">1.00</commonCountingTime>
				<intensities unit="counts">0 0 0 0 0 0 0 1 0 0 0 0 0 1 0 0 0 0 0 1 0 0 0 0 0 0 0 0 0 0 0 0 0 0 0 0 0 0 1 0 0 0 2 0 0 0 0 0 0 0 0 0 0 0 0 1 0 0 0 0 1 0 0 0 0 0 1 0 0 0 0 2 0 1 0 0 1 0 1 1 0 0 0 0 0 0 1 0 0 0 1 0 0 0 0 1 0 0 0 0 0 1 0 1 1 0 1 0 1 0 1 0 0 0 0 0 0 1 0 0 1 0 0 1 1 0 1 1 0 1 1 1 0 2 1 0 0 1 1 0 0 0 1 0 0 1 0 0 1 1 2 1 1 1 0 1 0 1 0 0 0 1 2 1 2 3 1 1 0 3 0 1 0 1 2 0 0 1 0 1 4 2 1 4 1 3 0 2 0 1 4 2 3 1 3 1 2 2 0 5 3 0 4 3 2 3 4 4 3 2 2 3 4 3 1 2 3 4 0 3 0 6 2 4 2 1 1 2 0 1 2 1 3 0 0 0 2 3 3</intensities>
			</dataPoints>
		</scan>
		<scan appendNumber="0" mode="Continuous" scanAxis="Omega-2Theta" status="Completed">
			<header>
				<startTimeStamp>2004-12-16T23:10:17+01:00</startTimeStamp>
				<endTimeStamp>2004-12-16T23:14:19+01:00</endTimeStamp>
				<author>
					<name>MFF</name>
				</author>
				<source>
					<applicationSoftware version="2.0d">X'Pert Data Collector</applicationSoftware>
					<instrumentControlSoftware version="1.4 ">XPERT-PRO</instrumentControlSoftware>
					<instrumentID>0000000000005097</instrumentID>
				</source>
			</header>
			<scanAxisCenter>
				<position axis="2Theta" unit="deg">151.4814</position>
				<position axis="Omega" unit="deg">87.0921</position>
			</scanAxisCenter>
			<reflection>
				<material>GaAs [001]</material>
				<hkl>
					<h>1</h>
					<k>1</k>
					<l>7</l>
				</hkl>
				<unitCell>
					<alpha unit="deg">90.00000</alpha>
					<beta unit="deg">90.00000</beta>
					<gamma unit="deg">90.00000</gamma>
					<a unit="Angstrom">5.65368</a>
					<b unit="Angstrom">5.65368</b>
					<c unit="Angstrom">5.65368</c>
				</unitCell>
			</reflection>
			<dataPoints>
				<positions axis="2Theta" unit="deg">
					<startPosition>149.1014</startPosition>
					<endPosition>153.8614</endPosition>
				</positions>
				<positions axis="Omega" unit="deg">
					<startPosition>85.9021</startPosition>
					<endPosition>88.2821</endPosition>
				</positions>
				<positions axis="Phi" unit="deg">
					<commonPosition>180.00</commonPosition>
				</positions>
				<positions axis="Psi" unit="deg">
					<commonPosition>1.45</commonPosition>
				</positions>
				<positions axis="X" unit="mm">
					<commonPosition>3.00</commonPosition>
				</positions>
				<positions axis="Y" unit="mm">
					<commonPosition>23.50</commonPosition>
				</positions>
				<positions axis="Z" unit="mm">
					<commonPosition>8.073</commonPosition>
				</positions>
				<commonCountingTime unit="seconds">1.00</commonCountingTime>
				<intensities unit="counts">0 0 0 0 0 0 0 2 1 0 0 2 0 0 0 0 1 1 0 0 0 0 0 0 0 0 0 0 0 0 0 1 1 0 1 0 0 0 1 0 0 0 1 0 0 0 2 1 0 0 0 0 0 1 1 0 0 0 0 0 1 0 0 0 1 0 0 0 0 0 0 0 0 2 0 0 1 0 0 1 0 0 0 0 0 1 0 0 0 0 0 0 0 0 0 1 0 1 0 0 0 1 0 0 2 0 1 0 1 2 0 1 0 0 0 0 0 1 0 1 0 0 0 0 1 0 0 0 0 0 0 1 1 1 1 1 1 1 0 0 0 1 1 0 0 0 1 0 0 1 0 0 0 0 0 1 0 0 0 0 2 0 0 0 0 1 2 2 1 1 1 0 1 2 1 2 2 4 1 0 1 1 1 1 1 2 0 0 2 2 0 2 1 0 1 1 1 2 3 2 2 4 3 3 4 5 2 6 3 6 4 4 1 2 5 4 2 9 0 3 5 2 4 2 1 1 1 2 1 1 1 1 1 0 1 4 0 1 3</intensities>
			</dataPoints>
		</scan>
		<scan appendNumber="0" mode="Continuous" scanAxis="Omega-2Theta" status="Completed">
			<header>
				<startTimeStamp>2004-12-16T23:14:31+01:00</startTimeStamp>
				<endTimeStamp>2004-12-16T23:18:33+01:00</endTimeStamp>
				<author>
					<name>MFF</name>
				</author>
				<source>
					<applicationSoftware version="2.0d">X'Pert Data Collector</applicationSoftware>
					<instrumentControlSoftware version="1.4 ">XPERT-PRO</instrumentControlSoftware>
					<instrumentID>0000000000005097</instrumentID>
				</source>
			</header>
			<scanAxisCenter>
				<position axis="2Theta" unit="deg">151.4814</position>
				<position axis="Omega" unit="deg">87.0931</position>
			</scanAxisCenter>
			<reflection>
				<material>GaAs [001]</material>
				<hkl>
					<h>1</h>
					<k>1</k>
					<l>7</l>
				</hkl>
				<unitCell>
					<alpha unit="deg">90.00000</alpha>
					<beta unit="deg">90.00000</beta>
					<gamma unit="deg">90.00000</gamma>
					<a unit="Angstrom">5.65368</a>
					<b unit="Angstrom">5.65368</b>
					<c unit="Angstrom">5.65368</c>
				</unitCell>
			</reflection>
			<dataPoints>
				<positions axis="2Theta" unit="deg">
					<startPosition>149.1014</startPosition>
					<endPosition>153.8614</endPosition>
				</positions>
				<positions axis="Omega" unit="deg">
					<startPosition>85.9031</startPosition>
					<endPosition>88.2831</endPosition>
				</positions>
				<positions axis="Phi" unit="deg">
					<commonPosition>180.00</commonPosition>
				</positions>
				<positions axis="Psi" unit="deg">
					<commonPosition>1.45</commonPosition>
				</positions>
				<positions axis="X" unit="mm">
					<commonPosition>3.00</commonPosition>
				</positions>
				<positions axis="Y" unit="mm">
					<commonPosition>23.50</commonPosition>
				</positions>
				<positions axis="Z" unit="mm">
					<commonPosition>8.073</commonPosition>
				</positions>
				<commonCountingTime unit="seconds">1.00</commonCountingTime>
				<intensities unit="counts">1 0 0 1 1 1 0 0 0 0 0 1 2 0 0 0 0 0 1 1 0 0 2 0 0 0 0 1 0 0 0 1 1 1 0 0 0 1 0 0 0 1 0 1 0 1 1 0 1 1 0 0 0 0 0 0 0 2 1 2 0 1 0 0 0 0 0 0 0 0 0 1 0 0 0 0 0 0 0 2 1 0 1 0 1 0 1 2 0 0 0 1 0 1 1 0 0 2 0 0 1 1 1 0 0 0 0 0 0 0 1 1 1 1 2 0 0 0 1 0 1 1 0 0 0 0 1 0 0 1 1 0 2 0 1 1 0 0 2 0 0 0 1 0 0 1 2 2 0 1 1 2 1 1 3 0 3 0 2 0 0 2 2 0 0 1 1 1 1 0 1 0 1 2 2 2 1 2 0 1 1 0 1 2 2 4 2 0 1 1 3 1 4 1 1 1 2 2 5 1 2 2 1 2 7 7 3 4 2 1 0 3 3 5 1 5 2 2 4 3 2 2 1 1 4 2 4 1 3 2 1 6 1 1 1 3 2 2 0</intensities>
			</dataPoints>
		</scan>
		<scan appendNumber="0" mode="Continuous" scanAxis="Omega-2Theta" status="Completed">
			<header>
				<startTimeStamp>2004-12-16T23:18:43+01:00</startTimeStamp>
				<endTimeStamp>2004-12-16T23:22:45+01:00</endTimeStamp>
				<author>
					<name>MFF</name>
				</author>
				<source>
					<applicationSoftware version="2.0d">X'Pert Data Collector</applicationSoftware>
					<instrumentControlSoftware version="1.4 ">XPERT-PRO</instrumentControlSoftware>
					<instrumentID>0000000000005097</instrumentID>
				</source>
			</header>
			<scanAxisCenter>
				<position axis="2Theta" unit="deg">151.4814</position>
				<position axis="Omega" unit="deg">87.0941</position>
			</scanAxisCenter>
			<reflection>
				<material>GaAs [001]</material>
				<hkl>
					<h>1</h>
					<k>1</k>
					<l>7</l>
				</hkl>
				<unitCell>
					<alpha unit="deg">90.00000</alpha>
					<beta unit="deg">90.00000</beta>
					<gamma unit="deg">90.00000</gamma>
					<a unit="Angstrom">5.65368</a>
					<b unit="Angstrom">5.65368</b>
					<c unit="Angstrom">5.65368</c>
				</unitCell>
			</reflection>
			<dataPoints>
				<positions axis="2Theta" unit="deg">
					<startPosition>149.1014</startPosition>
					<endPosition>153.8614</endPosition>
				</positions>
				<positions axis="Omega" unit="deg">
					<startPosition>85.9041</startPosition>
					<endPosition>88.2841</endPosition>
				</positions>
				<positions axis="Phi" unit="deg">
					<commonPosition>180.00</commonPosition>
				</positions>
				<positions axis="Psi" unit="deg">
					<commonPosition>1.45</commonPosition>
				</positions>
				<positions axis="X" unit="mm">
					<commonPosition>3.00</commonPosition>
				</positions>
				<positions axis="Y" unit="mm">
					<commonPosition>23.50</commonPosition>
				</positions>
				<positions axis="Z" unit="mm">
					<commonPosition>8.073</commonPosition>
				</positions>
				<commonCountingTime unit="seconds">1.00</commonCountingTime>
				<intensities unit="counts">0 1 0 0 1 0 0 1 2 2 0 1 0 0 1 0 0 0 1 1 0 0 1 1 1 0 0 0 0 0 0 0 0 1 0 0 0 1 0 0 0 0 0 0 0 0 0 0 1 0 1 1 0 1 0 0 0 1 0 0 0 0 0 2 0 2 1 0 0 1 0 1 0 1 0 0 0 0 0 1 0 0 0 0 0 1 0 0 1 0 0 0 0 0 0 2 0 0 1 0 2 1 1 0 0 0 0 0 0 0 0 0 0 1 0 1 0 1 0 1 0 0 0 1 0 0 0 0 1 0 2 0 1 0 0 1 1 1 0 0 0 0 0 1 0 2 1 0 2 0 0 2 0 0 0 4 3 1 0 0 0 2 0 1 0 3 1 0 1 1 1 1 1 1 1 0 0 1 1 3 1 2 2 0 4 3 0 2 1 4 1 0 2 1 1 1 2 3 7 3 1 2 4 4 4 3 3 3 0 6 2 2 6 0 3 5 6 2 4 2 3 4 2 3 0 3 3 2 2 2 0 3 1 0 1 1 2 1 1</intensities>
			</dataPoints>
		</scan>
		<scan appendNumber="0" mode="Continuous" scanAxis="Omega-2Theta" status="Completed">
			<header>
				<startTimeStamp>2004-12-16T23:22:59+01:00</startTimeStamp>
				<endTimeStamp>2004-12-16T23:27:01+01:00</endTimeStamp>
				<author>
					<name>MFF</name>
				</author>
				<source>
					<applicationSoftware version="2.0d">X'Pert Data Collector</applicationSoftware>
					<instrumentControlSoftware version="1.4 ">XPERT-PRO</instrumentControlSoftware>
					<instrumentID>0000000000005097</instrumentID>
				</source>
			</header>
			<scanAxisCenter>
				<position axis="2Theta" unit="deg">151.4814</position>
				<position axis="Omega" unit="deg">87.0951</position>
			</scanAxisCenter>
			<reflection>
				<material>GaAs [001]</material>
				<hkl>
					<h>1</h>
					<k>1</k>
					<l>7</l>
				</hkl>
				<unitCell>
					<alpha unit="deg">90.00000</alpha>
					<beta unit="deg">90.00000</beta>
					<gamma unit="deg">90.00000</gamma>
					<a unit="Angstrom">5.65368</a>
					<b unit="Angstrom">5.65368</b>
					<c unit="Angstrom">5.65368</c>
				</unitCell>
			</reflection>
			<dataPoints>
				<positions axis="2Theta" unit="deg">
					<startPosition>149.1014</startPosition>
					<endPosition>153.8614</endPosition>
				</positions>
				<positions axis="Omega" unit="deg">
					<startPosition>85.9051</startPosition>
					<endPosition>88.2851</endPosition>
				</positions>
				<positions axis="Phi" unit="deg">
					<commonPosition>180.00</commonPosition>
				</positions>
				<positions axis="Psi" unit="deg">
					<commonPosition>1.45</commonPosition>
				</positions>
				<positions axis="X" unit="mm">
					<commonPosition>3.00</commonPosition>
				</positions>
				<positions axis="Y" unit="mm">
					<commonPosition>23.50</commonPosition>
				</positions>
				<positions axis="Z" unit="mm">
					<commonPosition>8.073</commonPosition>
				</positions>
				<commonCountingTime unit="seconds">1.00</commonCountingTime>
[...]
			</dataPoints>
		</scan>
		<scan appendNumber="0" mode="Continuous" scanAxis="Omega-2Theta" status="Completed">
			<header>
				<startTimeStamp>2004-12-17T12:06:03+01:00</startTimeStamp>
				<endTimeStamp>2004-12-17T12:10:05+01:00</endTimeStamp>
				<author>
					<name>MFF</name>
				</author>
				<source>
					<applicationSoftware version="2.0d">X'Pert Data Collector</applicationSoftware>
					<instrumentControlSoftware version="1.4 ">XPERT-PRO</instrumentControlSoftware>
					<instrumentID>0000000000005097</instrumentID>
				</source>
			</header>
			<scanAxisCenter>
				<position axis="2Theta" unit="deg">151.4814</position>
				<position axis="Omega" unit="deg">87.2741</position>
			</scanAxisCenter>
			<reflection>
				<material>GaAs [001]</material>
				<hkl>
					<h>1</h>
					<k>1</k>
					<l>7</l>
				</hkl>
				<unitCell>
					<alpha unit="deg">90.00000</alpha>
					<beta unit="deg">90.00000</beta>
					<gamma unit="deg">90.00000</gamma>
					<a unit="Angstrom">5.65368</a>
					<b unit="Angstrom">5.65368</b>
					<c unit="Angstrom">5.65368</c>
				</unitCell>
			</reflection>
			<dataPoints>
				<positions axis="2Theta" unit="deg">
					<startPosition>149.1014</startPosition>
					<endPosition>153.8614</endPosition>
				</positions>
				<positions axis="Omega" unit="deg">
					<startPosition>86.0841</startPosition>
					<endPosition>88.4641</endPosition>
				</positions>
				<positions axis="Phi" unit="deg">
					<commonPosition>180.00</commonPosition>
				</positions>
				<positions axis="Psi" unit="deg">
					<commonPosition>1.45</commonPosition>
				</positions>
				<positions axis="X" unit="mm">
					<commonPosition>3.00</commonPosition>
				</positions>
				<positions axis="Y" unit="mm">
					<commonPosition>23.50</commonPosition>
				</positions>
				<positions axis="Z" unit="mm">
					<commonPosition>8.073</commonPosition>
				</positions>
				<commonCountingTime unit="seconds">1.00</commonCountingTime>
				<intensities unit="counts">0 0 1 0 0 0 2 0 1 0 0 0 0 0 0 1 0 1 0 0 0 0 0 0 0 1 0 0 0 0 1 0 0 0 0 0 0 0 0 0 0 1 0 0 0 1 0 0 1 0 0 0 0 0 0 1 0 0 0 0 2 0 0 0 0 0 2 0 1 0 2 0 0 1 0 0 0 0 1 0 0 1 0 0 0 0 0 2 3 0 0 0 0 0 0 0 0 0 0 0 0 0 0 1 0 0 0 0 0 0 0 0 0 0 0 0 1 0 1 1 3 0 3 1 0 1 1 0 0 0 0 0 0 1 1 0 0 0 0 0 0 0 1 1 1 0 2 0 0 1 0 0 0 2 0 0 1 1 0 0 1 0 1 1 0 2 0 1 1 0 1 2 1 1 0 1 0 1 2 0 1 2 1 0 1 2 3 1 1 0 1 2 1 0 1 3 0 0 1 1 1 0 0 1 0 3 2 0 1 4 0 0 0 1 1 1 1 1 0 1 2 0 1 1 1 0 0 3 0 1 1 1 2 0 0 1 1 0 0</intensities>
			</dataPoints>
		</scan>
		<scan appendNumber="0" mode="Continuous" scanAxis="Omega-2Theta" status="Completed">
			<header>
				<startTimeStamp>2004-12-17T12:10:21+01:00</startTimeStamp>
				<endTimeStamp>2004-12-17T12:14:23+01:00</endTimeStamp>
				<author>
					<name>MFF</name>
				</author>
				<source>
					<applicationSoftware version="2.0d">X'Pert Data Collector</applicationSoftware>
					<instrumentControlSoftware version="1.4 ">XPERT-PRO</instrumentControlSoftware>
					<instrumentID>0000000000005097</instrumentID>
				</source>
			</header>
			<scanAxisCenter>
				<position axis="2Theta" unit="deg">151.4814</position>
				<position axis="Omega" unit="deg">87.2751</position>
			</scanAxisCenter>
			<reflection>
				<material>GaAs [001]</material>
				<hkl>
					<h>1</h>
					<k>1</k>
					<l>7</l>
				</hkl>
				<unitCell>
					<alpha unit="deg">90.00000</alpha>
					<beta unit="deg">90.00000</beta>
					<gamma unit="deg">90.00000</gamma>
					<a unit="Angstrom">5.65368</a>
					<b unit="Angstrom">5.65368</b>
					<c unit="Angstrom">5.65368</c>
				</unitCell>
			</reflection>
			<dataPoints>
				<positions axis="2Theta" unit="deg">
					<startPosition>149.1014</startPosition>
					<endPosition>153.8614</endPosition>
				</positions>
				<positions axis="Omega" unit="deg">
					<startPosition>86.0851</startPosition>
					<endPosition>88.4651</endPosition>
				</positions>
				<positions axis="Phi" unit="deg">
					<commonPosition>180.00</commonPosition>
				</positions>
				<positions axis="Psi" unit="deg">
					<commonPosition>1.45</commonPosition>
				</positions>
				<positions axis="X" unit="mm">
					<commonPosition>3.00</commonPosition>
				</positions>
				<positions axis="Y" unit="mm">
					<commonPosition>23.50</commonPosition>
				</positions>
				<positions axis="Z" unit="mm">
					<commonPosition>8.073</commonPosition>
				</positions>
				<commonCountingTime unit="seconds">1.00</commonCountingTime>
				<intensities unit="counts">0 1 0 0 0 0 0 0 1 0 1 0 0 0 3 0 0 0 1 0 0 0 1 0 1 0 0 0 0 0 1 0 0 0 0 0 0 0 0 1 0 1 0 0 0 0 0 2 0 0 0 1 0 2 1 1 0 1 0 0 0 0 0 1 1 0 0 0 0 0 0 0 0 1 0 1 1 0 0 0 1 1 0 1 0 0 0 0 0 0 0 0 1 1 0 0 0 0 0 0 0 0 2 0 1 1 0 0 0 0 2 0 1 0 0 0 0 0 0 0 0 0 1 0 0 0 0 0 1 0 0 1 0 0 0 0 1 0 0 0 3 1 0 0 1 0 2 2 1 1 2 0 0 2 1 1 1 2 1 1 1 1 1 0 1 0 0 0 1 0 1 0 1 1 1 1 1 1 0 0 1 3 1 1 0 1 1 0 0 4 1 0 0 1 2 2 3 2 1 0 0 0 2 0 2 0 2 2 3 1 1 3 1 0 0 0 2 1 3 1 0 0 0 1 1 1 0 0 2 1 3 2 1 4 1 0 0 0 0</intensities>
			</dataPoints>
		</scan>
		<scan appendNumber="0" mode="Continuous" scanAxis="Omega-2Theta" status="Completed">
			<header>
				<startTimeStamp>2004-12-17T12:14:39+01:00</startTimeStamp>
				<endTimeStamp>2004-12-17T12:18:45+01:00</endTimeStamp>
				<author>
					<name>MFF</name>
				</author>
				<source>
					<applicationSoftware version="2.0d">X'Pert Data Collector</applicationSoftware>
					<instrumentControlSoftware version="1.4 ">XPERT-PRO</instrumentControlSoftware>
					<instrumentID>0000000000005097</instrumentID>
				</source>
			</header>
			<scanAxisCenter>
				<position axis="2Theta" unit="deg">151.4814</position>
				<position axis="Omega" unit="deg">87.2761</position>
			</scanAxisCenter>
			<reflection>
				<material>GaAs [001]</material>
				<hkl>
					<h>1</h>
					<k>1</k>
					<l>7</l>
				</hkl>
				<unitCell>
					<alpha unit="deg">90.00000</alpha>
					<beta unit="deg">90.00000</beta>
					<gamma unit="deg">90.00000</gamma>
					<a unit="Angstrom">5.65368</a>
					<b unit="Angstrom">5.65368</b>
					<c unit="Angstrom">5.65368</c>
				</unitCell>
			</reflection>
			<dataPoints>
				<positions axis="2Theta" unit="deg">
					<startPosition>149.1014</startPosition>
					<endPosition>153.8614</endPosition>
				</positions>
				<positions axis="Omega" unit="deg">
					<startPosition>86.0861</startPosition>
					<endPosition>88.4661</endPosition>
				</positions>
				<positions axis="Phi" unit="deg">
					<commonPosition>180.00</commonPosition>
				</positions>
				<positions axis="Psi" unit="deg">
					<commonPosition>1.45</commonPosition>
				</positions>
				<positions axis="X" unit="mm">
					<commonPosition>3.00</commonPosition>
				</positions>
				<positions axis="Y" unit="mm">
					<commonPosition>23.50</commonPosition>
				</positions>
				<positions axis="Z" unit="mm">
					<commonPosition>8.073</commonPosition>
				</positions>
				<commonCountingTime unit="seconds">1.00</commonCountingTime>
				<intensities unit="counts">0 1 0 0 0 0 0 0 0 0 0 0 0 0 0 0 0 0 0 0 0 0 0 0 0 1 0 0 0 0 0 0 0 0 2 0 0 0 0 1 0 0 0 1 0 0 0 1 0 0 1 0 0 1 3 0 2 0 0 1 3 0 0 0 0 1 0 0 0 0 0 0 0 0 0 0 0 0 0 1 0 0 0 0 0 0 0 0 0 0 0 0 0 0 1 0 1 0 0 0 2 0 0 0 1 1 0 1 0 0 0 0 0 0 0 1 0 0 0 1 1 0 1 0 0 0 0 1 0 1 1 0 0 0 0 1 1 1 0 0 0 1 1 0 0 2 1 1 1 2 1 0 1 1 1 1 0 1 0 0 0 2 3 0 1 0 0 2 1 0 0 0 0 0 0 2 2 1 2 0 1 0 0 0 1 0 1 1 0 1 0 1 2 0 1 1 1 3 0 1 0 0 1 0 1 2 1 2 0 1 1 1 2 1 4 1 2 0 0 1 1 1 2 1 0 0 0 0 1 0 1 0 0 0 2 0 1 0 2</intensities>
			</dataPoints>
		</scan>
		<scan appendNumber="0" mode="Continuous" scanAxis="Omega-2Theta" status="Completed">
			<header>
				<startTimeStamp>2004-12-17T12:19:02+01:00</startTimeStamp>
				<endTimeStamp>2004-12-17T12:23:04+01:00</endTimeStamp>
				<author>
					<name>MFF</name>
				</author>
				<source>
					<applicationSoftware version="2.0d">X'Pert Data Collector</applicationSoftware>
					<instrumentControlSoftware version="1.4 ">XPERT-PRO</instrumentControlSoftware>
					<instrumentID>0000000000005097</instrumentID>
				</source>
			</header>
			<scanAxisCenter>
				<position axis="2Theta" unit="deg">151.4814</position>
				<position axis="Omega" unit="deg">87.2771</position>
			</scanAxisCenter>
			<reflection>
				<material>GaAs [001]</material>
				<hkl>
					<h>1</h>
					<k>1</k>
					<l>7</l>
				</hkl>
				<unitCell>
					<alpha unit="deg">90.00000</alpha>
					<beta unit="deg">90.00000</beta>
					<gamma unit="deg">90.00000</gamma>
					<a unit="Angstrom">5.65368</a>
					<b unit="Angstrom">5.65368</b>
					<c unit="Angstrom">5.65368</c>
				</unitCell>
			</reflection>
			<dataPoints>
				<positions axis="2Theta" unit="deg">
					<startPosition>149.1014</startPosition>
					<endPosition>153.8614</endPosition>
				</positions>
				<positions axis="Omega" unit="deg">
					<startPosition>86.0871</startPosition>
					<endPosition>88.4671</endPosition>
				</positions>
				<positions axis="Phi" unit="deg">
					<commonPosition>180.00</commonPosition>
				</positions>
				<positions axis="Psi" unit="deg">
					<commonPosition>1.45</commonPosition>
				</positions>
				<positions axis="X" unit="mm">
					<commonPosition>3.00</commonPosition>
				</positions>
				<positions axis="Y" unit="mm">
					<commonPosition>23.50</commonPosition>
				</positions>
				<positions axis="Z" unit="mm">
					<commonPosition>8.073</commonPosition>
				</positions>
				<commonCountingTime unit="seconds">1.00</commonCountingTime>
				<intensities unit="counts">0 0 0 0 0 0 0 0 1 1 1 0 0 0 0 0 0 0 0 0 1 0 0 0 0 0 0 0 0 0 1 1 2 0 0 0 2 1 0 0 0 0 0 0 1 0 0 1 0 0 0 1 0 0 1 0 0 0 0 0 0 0 0 2 0 0 0 0 0 0 2 0 2 0 1 0 0 0 0 4 1 1 0 0 0 0 1 1 0 1 0 0 0 1 2 1 0 0 0 0 0 2 0 0 0 2 0 0 0 0 0 2 1 0 1 0 0 0 1 1 1 0 1 3 0 1 3 3 2 0 0 1 1 1 0 0 1 1 2 0 1 0 0 0 1 0 2 0 0 0 1 1 1 0 0 1 1 0 1 1 0 0 0 2 1 1 1 1 0 1 1 1 1 0 0 0 0 2 1 1 0 2 1 2 0 1 0 1 2 0 0 2 0 3 3 0 2 0 0 0 0 0 0 2 1 1 1 2 1 2 2 3 2 0 0 2 1 0 0 0 1 3 0 1 0 1 3 1 0 0 0 1 0 1 1 1 0 0 0</intensities>
			</dataPoints>
		</scan>
		<scan appendNumber="0" mode="Continuous" scanAxis="Omega-2Theta" status="Completed">
			<header>
				<startTimeStamp>2004-12-17T12:23:19+01:00</startTimeStamp>
				<endTimeStamp>2004-12-17T12:27:20+01:00</endTimeStamp>
				<author>
					<name>MFF</name>
				</author>
				<source>
					<applicationSoftware version="2.0d">X'Pert Data Collector</applicationSoftware>
					<instrumentControlSoftware version="1.4 ">XPERT-PRO</instrumentControlSoftware>
					<instrumentID>0000000000005097</instrumentID>
				</source>
			</header>
			<scanAxisCenter>
				<position axis="2Theta" unit="deg">151.4814</position>
				<position axis="Omega" unit="deg">87.2781</position>
			</scanAxisCenter>
			<reflection>
				<material>GaAs [001]</material>
				<hkl>
					<h>1</h>
					<k>1</k>
					<l>7</l>
				</hkl>
				<unitCell>
					<alpha unit="deg">90.00000</alpha>
					<beta unit="deg">90.00000</beta>
					<gamma unit="deg">90.00000</gamma>
					<a unit="Angstrom">5.65368</a>
					<b unit="Angstrom">5.65368</b>
					<c unit="Angstrom">5.65368</c>
				</unitCell>
			</reflection>
			<dataPoints>
				<positions axis="2Theta" unit="deg">
					<startPosition>149.1014</startPosition>
					<endPosition>153.8614</endPosition>
				</positions>
				<positions axis="Omega" unit="deg">
					<startPosition>86.0881</startPosition>
					<endPosition>88.4681</endPosition>
				</positions>
				<positions axis="Phi" unit="deg">
					<commonPosition>180.00</commonPosition>
				</positions>
				<positions axis="Psi" unit="deg">
					<commonPosition>1.45</commonPosition>
				</positions>
				<positions axis="X" unit="mm">
					<commonPosition>3.00</commonPosition>
				</positions>
				<positions axis="Y" unit="mm">
					<commonPosition>23.50</commonPosition>
				</positions>
				<positions axis="Z" unit="mm">
					<commonPosition>8.073</commonPosition>
				</positions>
				<commonCountingTime unit="seconds">1.00</commonCountingTime>
				<intensities unit="counts">0 0 0 0 0 0 0 0 0 0 0 0 0 0 0 1 0 0 0 0 0 0 0 0 0 0 0 0 0 0 0 0 0 0 0 0 0 0 0 0 0 1 0 1 0 0 0 2 0 0 0 0 0 0 0 0 0 0 1 0 0 1 0 0 1 1 1 0 1 0 0 1 1 0 1 0 0 0 0 1 3 0 0 1 0 1 1 0 1 1 0 0 0 1 0 1 0 0 0 1 2 1 1 0 0 0 0 0 0 0 1 0 2 0 1 0 0 1 0 0 2 0 0 4 0 0 1 0 1 1 0 0 0 1 2 1 0 1 1 0 0 1 0 0 1 2 1 1 0 1 2 0 2 3 1 1 1 0 1 1 0 3 1 0 4 0 0 3 1 1 1 1 0 0 0 0 0 0 0 0 1 1 2 0 3 1 0 1 1 1 0 0 0 2 0 1 1 1 2 0 0 0 1 1 0 0 1 0 1 0 1 0 1 0 1 0 0 0 1 0 1 0 0 1 1 1 0 0 1 1 1 0 0 0 0 1 2 0 0</intensities>
			</dataPoints>
		</scan>
		<scan appendNumber="0" mode="Continuous" scanAxis="Omega-2Theta" status="Completed">
			<header>
				<startTimeStamp>2004-12-17T12:27:36+01:00</startTimeStamp>
				<endTimeStamp>2004-12-17T12:31:38+01:00</endTimeStamp>
				<author>
					<name>MFF</name>
				</author>
				<source>
					<applicationSoftware version="2.0d">X'Pert Data Collector</applicationSoftware>
					<instrumentControlSoftware version="1.4 ">XPERT-PRO</instrumentControlSoftware>
					<instrumentID>0000000000005097</instrumentID>
				</source>
			</header>
			<scanAxisCenter>
				<position axis="2Theta" unit="deg">151.4814</position>
				<position axis="Omega" unit="deg">87.2791</position>
			</scanAxisCenter>
			<reflection>
				<material>GaAs [001]</material>
				<hkl>
					<h>1</h>
					<k>1</k>
					<l>7</l>
				</hkl>
				<unitCell>
					<alpha unit="deg">90.00000</alpha>
					<beta unit="deg">90.00000</beta>
					<gamma unit="deg">90.00000</gamma>
					<a unit="Angstrom">5.65368</a>
					<b unit="Angstrom">5.65368</b>
					<c unit="Angstrom">5.65368</c>
				</unitCell>
			</reflection>
			<dataPoints>
				<positions axis="2Theta" unit="deg">
					<startPosition>149.1014</startPosition>
					<endPosition>153.8614</endPosition>
				</positions>
				<positions axis="Omega" unit="deg">
					<startPosition>86.0891</startPosition>
					<endPosition>88.4691</endPosition>
				</positions>
				<positions axis="Phi" unit="deg">
					<commonPosition>180.00</commonPosition>
				</positions>
				<positions axis="Psi" unit="deg">
					<commonPosition>1.45</commonPosition>
				</positions>
				<positions axis="X" unit="mm">
					<commonPosition>3.00</commonPosition>
				</positions>
				<positions axis="Y" unit="mm">
					<commonPosition>23.50</commonPosition>
				</positions>
				<positions axis="Z" unit="mm">
					<commonPosition>8.073</commonPosition>
				</positions>
				<commonCountingTime unit="seconds">1.00</commonCountingTime>
				<intensities unit="counts">1 0 0 1 0 1 0 1 0 0 0 0 0 1 0 1 0 0 0 1 0 0 0 0 0 0 0 0 1 1 0 0 0 1 0 0 0 0 0 0 0 0 0 2 1 1 1 1 0 0 0 1 1 1 0 0 0 0 0 0 0 1 0 0 0 0 0 0 0 1 0 1 0 0 0 0 0 1 0 0 0 0 1 0 0 0 1 0 0 0 1 0 1 0 1 1 0 0 0 1 0 0 1 0 1 0 1 1 1 1 0 0 1 0 0 3 0 0 0 0 0 0 0 0 1 1 0 0 0 1 0 0 0 0 0 0 0 2 0 1 0 1 1 1 0 3 1 1 2 2 2 1 0 0 1 1 0 2 0 2 0 0 0 0 1 0 0 1 1 0 1 1 2 2 1 0 0 2 1 1 2 3 0 1 0 0 0 1 1 2 0 3 2 1 1 2 0 0 1 2 2 2 1 1 2 1 1 0 0 1 1 1 1 1 0 1 0 1 0 4 1 0 1 1 3 1 0 0 0 1 0 1 0 2 0 0 1 1 1</intensities>
			</dataPoints>
		</scan>
		<scan appendNumber="0" mode="Continuous" scanAxis="Omega-2Theta" status="Completed">
			<header>
				<startTimeStamp>2004-12-17T12:31:52+01:00</startTimeStamp>
				<endTimeStamp>2004-12-17T12:35:57+01:00</endTimeStamp>
				<author>
					<name>MFF</name>
				</author>
				<source>
					<applicationSoftware version="2.0d">X'Pert Data Collector</applicationSoftware>
					<instrumentControlSoftware version="1.4 ">XPERT-PRO</instrumentControlSoftware>
					<instrumentID>0000000000005097</instrumentID>
				</source>
			</header>
			<scanAxisCenter>
				<position axis="2Theta" unit="deg">151.4814</position>
				<position axis="Omega" unit="deg">87.2801</position>
			</scanAxisCenter>
			<reflection>
				<material>GaAs [001]</material>
				<hkl>
					<h>1</h>
					<k>1</k>
					<l>7</l>
				</hkl>
				<unitCell>
					<alpha unit="deg">90.00000</alpha>
					<beta unit="deg">90.00000</beta>
					<gamma unit="deg">90.00000</gamma>
					<a unit="Angstrom">5.65368</a>
					<b unit="Angstrom">5.65368</b>
					<c unit="Angstrom">5.65368</c>
				</unitCell>
			</reflection>
			<dataPoints>
				<positions axis="2Theta" unit="deg">
					<startPosition>149.1014</startPosition>
					<endPosition>153.8614</endPosition>
				</positions>
				<positions axis="Omega" unit="deg">
					<startPosition>86.0901</startPosition>
					<endPosition>88.4701</endPosition>
				</positions>
				<positions axis="Phi" unit="deg">
					<commonPosition>180.00</commonPosition>
				</positions>
				<positions axis="Psi" unit="deg">
					<commonPosition>1.45</commonPosition>
				</positions>
				<positions axis="X" unit="mm">
					<commonPosition>3.00</commonPosition>
				</positions>
				<positions axis="Y" unit="mm">
					<commonPosition>23.50</commonPosition>
				</positions>
				<positions axis="Z" unit="mm">
					<commonPosition>8.073</commonPosition>
				</positions>
				<commonCountingTime unit="seconds">1.00</commonCountingTime>
				<intensities unit="counts">0 0 0 0 0 0 0 0 0 0 0 0 0 0 0 1 0 0 1 0 0 0 0 1 0 0 0 0 0 0 0 0 0 0 1 2 0 0 1 0 0 1 0 1 0 0 0 0 0 0 0 0 0 0 0 1 1 1 0 0 0 0 0 0 0 1 0 1 1 0 0 0 0 0 0 0 0 0 0 0 0 0 1 0 0 0 0 1 0 0 0 0 0 0 1 0 0 0 0 0 0 0 0 0 0 0 0 0 0 0 0 3 0 2 2 0 0 0 1 0 0 1 0 0 0 0 0 0 0 0 0 0 0 0 1 0 1 1 0 0 0 0 0 0 1 0 0 0 3 0 1 0 0 0 2 1 1 1 2 2 0 3 0 1 0 1 2 1 0 0 0 0 0 0 1 1 0 0 1 1 1 1 1 0 1 1 2 0 1 0 1 0 0 0 0 1 2 0 1 1 0 0 0 4 0 0 1 2 0 2 0 0 1 2 0 1 0 0 0 1 1 2 2 2 1 0 0 0 0 1 1 1 2 1 0 0 0 2 0</intensities>
			</dataPoints>
		</scan>
		<scan appendNumber="0" mode="Continuous" scanAxis="Omega-2Theta" status="Completed">
			<header>
				<startTimeStamp>2004-12-17T12:36:12+01:00</startTimeStamp>
				<endTimeStamp>2004-12-17T12:40:14+01:00</endTimeStamp>
				<author>
					<name>MFF</name>
				</author>
				<source>
					<applicationSoftware version="2.0d">X'Pert Data Collector</applicationSoftware>
					<instrumentControlSoftware version="1.4 ">XPERT-PRO</instrumentControlSoftware>
					<instrumentID>0000000000005097</instrumentID>
				</source>
			</header>
			<scanAxisCenter>
				<position axis="2Theta" unit="deg">151.4814</position>
				<position axis="Omega" unit="deg">87.2811</position>
			</scanAxisCenter>
			<reflection>
				<material>GaAs [001]</material>
				<hkl>
					<h>1</h>
					<k>1</k>
					<l>7</l>
				</hkl>
				<unitCell>
					<alpha unit="deg">90.00000</alpha>
					<beta unit="deg">90.00000</beta>
					<gamma unit="deg">90.00000</gamma>
					<a unit="Angstrom">5.65368</a>
					<b unit="Angstrom">5.65368</b>
					<c unit="Angstrom">5.65368</c>
				</unitCell>
			</reflection>
			<dataPoints>
				<positions axis="2Theta" unit="deg">
					<startPosition>149.1014</startPosition>
					<endPosition>153.8614</endPosition>
				</positions>
				<positions axis="Omega" unit="deg">
					<startPosition>86.0911</startPosition>
					<endPosition>88.4711</endPosition>
				</positions>
				<positions axis="Phi" unit="deg">
					<commonPosition>180.00</commonPosition>
				</positions>
				<positions axis="Psi" unit="deg">
					<commonPosition>1.45</commonPosition>
				</positions>
				<positions axis="X" unit="mm">
					<commonPosition>3.00</commonPosition>
				</positions>
				<positions axis="Y" unit="mm">
					<commonPosition>23.50</commonPosition>
				</positions>
				<positions axis="Z" unit="mm">
					<commonPosition>8.073</commonPosition>
				</positions>
				<commonCountingTime unit="seconds">1.00</commonCountingTime>
				<intensities unit="counts">0 0 0 0 0 1 0 0 0 0 0 0 0 0 1 0 0 0 1 1 0 0 0 0 0 0 0 0 1 0 0 0 0 0 0 1 0 0 0 0 0 1 0 0 0 0 0 0 0 0 1 0 0 0 0 0 0 0 0 0 0 0 2 0 0 0 0 0 0 3 1 1 0 0 1 0 2 1 0 0 0 2 0 0 0 0 1 1 0 0 0 0 0 0 2 0 0 0 0 3 0 0 0 0 0 0 1 0 0 1 1 2 0 0 1 0 3 1 0 1 1 0 1 2 0 1 1 0 1 0 1 2 0 1 0 3 0 3 0 0 1 0 0 1 1 0 0 1 2 0 0 2 0 0 0 0 2 2 1 1 2 0 1 0 0 1 0 1 0 3 0 0 1 1 2 0 1 2 0 0 0 1 0 2 1 0 4 1 2 2 1 2 1 3 0 0 0 0 2 1 1 4 0 3 0 2 5 0 0 1 0 0 3 3 0 0 2 0 1 0 0 1 0 1 3 0 4 0 1 0 0 0 1 1 0 2 0 3 0</intensities>
			</dataPoints>
		</scan>
	</xrdMeasurement>
</xrdMeasurements>